[2024-10-21T02:40:21.593+0000] {taskinstance.py:1159} INFO - Dependencies all met for dep_context=non-requeueable deps ti=<TaskInstance: crypto_tickers_etl.transform scheduled__2024-10-07T00:00:00+00:00 [queued]>
[2024-10-21T02:40:21.608+0000] {taskinstance.py:1159} INFO - Dependencies all met for dep_context=requeueable deps ti=<TaskInstance: crypto_tickers_etl.transform scheduled__2024-10-07T00:00:00+00:00 [queued]>
[2024-10-21T02:40:21.609+0000] {taskinstance.py:1361} INFO - Starting attempt 1 of 2
[2024-10-21T02:40:21.693+0000] {taskinstance.py:1382} INFO - Executing <Task(PythonOperator): transform> on 2024-10-07 00:00:00+00:00
[2024-10-21T02:40:21.706+0000] {standard_task_runner.py:57} INFO - Started process 529 to run task
[2024-10-21T02:40:21.710+0000] {standard_task_runner.py:84} INFO - Running: ['***', 'tasks', 'run', 'crypto_tickers_etl', 'transform', 'scheduled__2024-10-07T00:00:00+00:00', '--job-id', '758', '--raw', '--subdir', 'DAGS_FOLDER/crypto_etl_dag.py', '--cfg-path', '/tmp/tmp_j_iift8']
[2024-10-21T02:40:21.712+0000] {standard_task_runner.py:85} INFO - Job 758: Subtask transform
[2024-10-21T02:40:21.825+0000] {task_command.py:416} INFO - Running <TaskInstance: crypto_tickers_etl.transform scheduled__2024-10-07T00:00:00+00:00 [running]> on host 9ef7466b1d1e
[2024-10-21T02:40:22.267+0000] {taskinstance.py:1662} INFO - Exporting env vars: AIRFLOW_CTX_DAG_OWNER='***' AIRFLOW_CTX_DAG_ID='crypto_tickers_etl' AIRFLOW_CTX_TASK_ID='transform' AIRFLOW_CTX_EXECUTION_DATE='2024-10-07T00:00:00+00:00' AIRFLOW_CTX_TRY_NUMBER='1' AIRFLOW_CTX_DAG_RUN_ID='scheduled__2024-10-07T00:00:00+00:00'
[2024-10-21T02:40:22.289+0000] {taskinstance.py:1937} ERROR - Task failed with exception
Traceback (most recent call last):
  File "/home/airflow/.local/lib/python3.8/site-packages/airflow/operators/python.py", line 192, in execute
    return_value = self.execute_callable()
  File "/home/airflow/.local/lib/python3.8/site-packages/airflow/operators/python.py", line 209, in execute_callable
    return self.python_callable(*self.op_args, **self.op_kwargs)
  File "/opt/airflow/dags/crypto_etl_dag.py", line 19, in transform_data
    tickers = data['tickers']
KeyError: 'tickers'
[2024-10-21T02:40:22.309+0000] {taskinstance.py:1400} INFO - Marking task as UP_FOR_RETRY. dag_id=crypto_tickers_etl, task_id=transform, execution_date=20241007T000000, start_date=20241021T024021, end_date=20241021T024022
[2024-10-21T02:40:22.481+0000] {standard_task_runner.py:104} ERROR - Failed to execute job 758 for task transform ('tickers'; 529)
[2024-10-21T02:40:22.526+0000] {local_task_job_runner.py:228} INFO - Task exited with return code 1
[2024-10-21T02:40:22.568+0000] {taskinstance.py:2778} INFO - 0 downstream tasks scheduled from follow-on schedule check
