[2024-10-21T15:37:50.452+0000] {taskinstance.py:1159} INFO - Dependencies all met for dep_context=non-requeueable deps ti=<TaskInstance: crypto_tickers1_etl.transform scheduled__2024-09-08T00:00:00+00:00 [queued]>
[2024-10-21T15:37:50.484+0000] {taskinstance.py:1159} INFO - Dependencies all met for dep_context=requeueable deps ti=<TaskInstance: crypto_tickers1_etl.transform scheduled__2024-09-08T00:00:00+00:00 [queued]>
[2024-10-21T15:37:50.485+0000] {taskinstance.py:1361} INFO - Starting attempt 1 of 2
[2024-10-21T15:37:50.523+0000] {taskinstance.py:1382} INFO - Executing <Task(PythonOperator): transform> on 2024-09-08 00:00:00+00:00
[2024-10-21T15:37:50.545+0000] {standard_task_runner.py:57} INFO - Started process 170 to run task
[2024-10-21T15:37:50.553+0000] {standard_task_runner.py:84} INFO - Running: ['***', 'tasks', 'run', 'crypto_tickers1_etl', 'transform', 'scheduled__2024-09-08T00:00:00+00:00', '--job-id', '825', '--raw', '--subdir', 'DAGS_FOLDER/25_6421605435_dag.py', '--cfg-path', '/tmp/tmpl3f1hvnm']
[2024-10-21T15:37:50.555+0000] {standard_task_runner.py:85} INFO - Job 825: Subtask transform
[2024-10-21T15:37:50.699+0000] {task_command.py:416} INFO - Running <TaskInstance: crypto_tickers1_etl.transform scheduled__2024-09-08T00:00:00+00:00 [running]> on host a32437856f27
[2024-10-21T15:37:50.927+0000] {taskinstance.py:1662} INFO - Exporting env vars: AIRFLOW_CTX_DAG_OWNER='***' AIRFLOW_CTX_DAG_ID='crypto_tickers1_etl' AIRFLOW_CTX_TASK_ID='transform' AIRFLOW_CTX_EXECUTION_DATE='2024-09-08T00:00:00+00:00' AIRFLOW_CTX_TRY_NUMBER='1' AIRFLOW_CTX_DAG_RUN_ID='scheduled__2024-09-08T00:00:00+00:00'
[2024-10-21T15:37:50.960+0000] {taskinstance.py:1937} ERROR - Task failed with exception
Traceback (most recent call last):
  File "/home/airflow/.local/lib/python3.8/site-packages/airflow/operators/python.py", line 192, in execute
    return_value = self.execute_callable()
  File "/home/airflow/.local/lib/python3.8/site-packages/airflow/operators/python.py", line 209, in execute_callable
    return self.python_callable(*self.op_args, **self.op_kwargs)
  File "/opt/airflow/dags/25_6421605435_dag.py", line 19, in transform_data
    tickers = data['tickers']
KeyError: 'tickers'
[2024-10-21T15:37:50.988+0000] {taskinstance.py:1400} INFO - Marking task as UP_FOR_RETRY. dag_id=crypto_tickers1_etl, task_id=transform, execution_date=20240908T000000, start_date=20241021T153750, end_date=20241021T153750
[2024-10-21T15:37:51.032+0000] {standard_task_runner.py:104} ERROR - Failed to execute job 825 for task transform ('tickers'; 170)
[2024-10-21T15:37:51.098+0000] {local_task_job_runner.py:228} INFO - Task exited with return code 1
[2024-10-21T15:37:51.178+0000] {taskinstance.py:2778} INFO - 0 downstream tasks scheduled from follow-on schedule check
