[2024-10-21T15:37:49.266+0000] {taskinstance.py:1159} INFO - Dependencies all met for dep_context=non-requeueable deps ti=<TaskInstance: crypto_tickers1_etl.transform scheduled__2024-09-07T00:00:00+00:00 [queued]>
[2024-10-21T15:37:49.307+0000] {taskinstance.py:1159} INFO - Dependencies all met for dep_context=requeueable deps ti=<TaskInstance: crypto_tickers1_etl.transform scheduled__2024-09-07T00:00:00+00:00 [queued]>
[2024-10-21T15:37:49.309+0000] {taskinstance.py:1361} INFO - Starting attempt 1 of 2
[2024-10-21T15:37:49.356+0000] {taskinstance.py:1382} INFO - Executing <Task(PythonOperator): transform> on 2024-09-07 00:00:00+00:00
[2024-10-21T15:37:49.383+0000] {standard_task_runner.py:57} INFO - Started process 162 to run task
[2024-10-21T15:37:49.391+0000] {standard_task_runner.py:84} INFO - Running: ['***', 'tasks', 'run', 'crypto_tickers1_etl', 'transform', 'scheduled__2024-09-07T00:00:00+00:00', '--job-id', '822', '--raw', '--subdir', 'DAGS_FOLDER/25_6421605435_dag.py', '--cfg-path', '/tmp/tmp5cqnm651']
[2024-10-21T15:37:49.394+0000] {standard_task_runner.py:85} INFO - Job 822: Subtask transform
[2024-10-21T15:37:49.534+0000] {task_command.py:416} INFO - Running <TaskInstance: crypto_tickers1_etl.transform scheduled__2024-09-07T00:00:00+00:00 [running]> on host a32437856f27
[2024-10-21T15:37:49.752+0000] {taskinstance.py:1662} INFO - Exporting env vars: AIRFLOW_CTX_DAG_OWNER='***' AIRFLOW_CTX_DAG_ID='crypto_tickers1_etl' AIRFLOW_CTX_TASK_ID='transform' AIRFLOW_CTX_EXECUTION_DATE='2024-09-07T00:00:00+00:00' AIRFLOW_CTX_TRY_NUMBER='1' AIRFLOW_CTX_DAG_RUN_ID='scheduled__2024-09-07T00:00:00+00:00'
[2024-10-21T15:37:49.792+0000] {taskinstance.py:1937} ERROR - Task failed with exception
Traceback (most recent call last):
  File "/home/airflow/.local/lib/python3.8/site-packages/airflow/operators/python.py", line 192, in execute
    return_value = self.execute_callable()
  File "/home/airflow/.local/lib/python3.8/site-packages/airflow/operators/python.py", line 209, in execute_callable
    return self.python_callable(*self.op_args, **self.op_kwargs)
  File "/opt/airflow/dags/25_6421605435_dag.py", line 19, in transform_data
    tickers = data['tickers']
KeyError: 'tickers'
[2024-10-21T15:37:49.834+0000] {taskinstance.py:1400} INFO - Marking task as UP_FOR_RETRY. dag_id=crypto_tickers1_etl, task_id=transform, execution_date=20240907T000000, start_date=20241021T153749, end_date=20241021T153749
[2024-10-21T15:37:49.873+0000] {standard_task_runner.py:104} ERROR - Failed to execute job 822 for task transform ('tickers'; 162)
[2024-10-21T15:37:49.939+0000] {local_task_job_runner.py:228} INFO - Task exited with return code 1
[2024-10-21T15:37:50.032+0000] {taskinstance.py:2778} INFO - 0 downstream tasks scheduled from follow-on schedule check
