[2024-10-20T02:53:07.365+0000] {taskinstance.py:1159} INFO - Dependencies all met for dep_context=non-requeueable deps ti=<TaskInstance: crypto_etl.load manual__2024-10-20T02:53:00.387436+00:00 [queued]>
[2024-10-20T02:53:07.378+0000] {taskinstance.py:1159} INFO - Dependencies all met for dep_context=requeueable deps ti=<TaskInstance: crypto_etl.load manual__2024-10-20T02:53:00.387436+00:00 [queued]>
[2024-10-20T02:53:07.378+0000] {taskinstance.py:1361} INFO - Starting attempt 1 of 2
[2024-10-20T02:53:07.396+0000] {taskinstance.py:1382} INFO - Executing <Task(PythonOperator): load> on 2024-10-20 02:53:00.387436+00:00
[2024-10-20T02:53:07.405+0000] {standard_task_runner.py:57} INFO - Started process 219 to run task
[2024-10-20T02:53:07.408+0000] {standard_task_runner.py:84} INFO - Running: ['***', 'tasks', 'run', 'crypto_etl', 'load', 'manual__2024-10-20T02:53:00.387436+00:00', '--job-id', '197', '--raw', '--subdir', 'DAGS_FOLDER/crypto_etl_dag.py', '--cfg-path', '/tmp/tmpfzp11o6c']
[2024-10-20T02:53:07.409+0000] {standard_task_runner.py:85} INFO - Job 197: Subtask load
[2024-10-20T02:53:07.467+0000] {task_command.py:416} INFO - Running <TaskInstance: crypto_etl.load manual__2024-10-20T02:53:00.387436+00:00 [running]> on host 6fb9dd1ce83c
[2024-10-20T02:53:07.575+0000] {taskinstance.py:1662} INFO - Exporting env vars: AIRFLOW_CTX_DAG_OWNER='***' AIRFLOW_CTX_DAG_ID='crypto_etl' AIRFLOW_CTX_TASK_ID='load' AIRFLOW_CTX_EXECUTION_DATE='2024-10-20T02:53:00.387436+00:00' AIRFLOW_CTX_TRY_NUMBER='1' AIRFLOW_CTX_DAG_RUN_ID='manual__2024-10-20T02:53:00.387436+00:00'
[2024-10-20T02:53:07.584+0000] {taskinstance.py:1937} ERROR - Task failed with exception
Traceback (most recent call last):
  File "/home/airflow/.local/lib/python3.8/site-packages/airflow/operators/python.py", line 192, in execute
    return_value = self.execute_callable()
  File "/home/airflow/.local/lib/python3.8/site-packages/airflow/operators/python.py", line 209, in execute_callable
    return self.python_callable(*self.op_args, **self.op_kwargs)
  File "/opt/airflow/dags/crypto_etl_dag.py", line 36, in load_to_db
    df = pd.read_csv(data_path)
  File "/home/airflow/.local/lib/python3.8/site-packages/pandas/io/parsers/readers.py", line 912, in read_csv
    return _read(filepath_or_buffer, kwds)
  File "/home/airflow/.local/lib/python3.8/site-packages/pandas/io/parsers/readers.py", line 577, in _read
    parser = TextFileReader(filepath_or_buffer, **kwds)
  File "/home/airflow/.local/lib/python3.8/site-packages/pandas/io/parsers/readers.py", line 1407, in __init__
    self._engine = self._make_engine(f, self.engine)
  File "/home/airflow/.local/lib/python3.8/site-packages/pandas/io/parsers/readers.py", line 1661, in _make_engine
    self.handles = get_handle(
  File "/home/airflow/.local/lib/python3.8/site-packages/pandas/io/common.py", line 859, in get_handle
    handle = open(
FileNotFoundError: [Errno 2] No such file or directory: '/test-airflow/airflow/data/crypto_prices_30_days.csv'
[2024-10-20T02:53:07.602+0000] {taskinstance.py:1400} INFO - Marking task as UP_FOR_RETRY. dag_id=crypto_etl, task_id=load, execution_date=20241020T025300, start_date=20241020T025307, end_date=20241020T025307
[2024-10-20T02:53:07.623+0000] {standard_task_runner.py:104} ERROR - Failed to execute job 197 for task load ([Errno 2] No such file or directory: '/test-airflow/airflow/data/crypto_prices_30_days.csv'; 219)
[2024-10-20T02:53:07.661+0000] {local_task_job_runner.py:228} INFO - Task exited with return code 1
[2024-10-20T02:53:07.682+0000] {taskinstance.py:2778} INFO - 0 downstream tasks scheduled from follow-on schedule check
