[2024-10-21T02:34:31.786+0000] {taskinstance.py:1159} INFO - Dependencies all met for dep_context=non-requeueable deps ti=<TaskInstance: crypto_tickers_etl.load scheduled__2024-09-06T00:00:00+00:00 [queued]>
[2024-10-21T02:34:31.815+0000] {taskinstance.py:1159} INFO - Dependencies all met for dep_context=requeueable deps ti=<TaskInstance: crypto_tickers_etl.load scheduled__2024-09-06T00:00:00+00:00 [queued]>
[2024-10-21T02:34:31.817+0000] {taskinstance.py:1361} INFO - Starting attempt 1 of 2
[2024-10-21T02:34:31.852+0000] {taskinstance.py:1382} INFO - Executing <Task(PythonOperator): load> on 2024-09-06 00:00:00+00:00
[2024-10-21T02:34:31.867+0000] {standard_task_runner.py:57} INFO - Started process 197 to run task
[2024-10-21T02:34:31.873+0000] {standard_task_runner.py:84} INFO - Running: ['***', 'tasks', 'run', 'crypto_tickers_etl', 'load', 'scheduled__2024-09-06T00:00:00+00:00', '--job-id', '674', '--raw', '--subdir', 'DAGS_FOLDER/crypto_etl_dag.py', '--cfg-path', '/tmp/tmp5b6afl9_']
[2024-10-21T02:34:31.876+0000] {standard_task_runner.py:85} INFO - Job 674: Subtask load
[2024-10-21T02:34:31.986+0000] {task_command.py:416} INFO - Running <TaskInstance: crypto_tickers_etl.load scheduled__2024-09-06T00:00:00+00:00 [running]> on host 9ef7466b1d1e
[2024-10-21T02:34:32.154+0000] {taskinstance.py:1662} INFO - Exporting env vars: AIRFLOW_CTX_DAG_OWNER='***' AIRFLOW_CTX_DAG_ID='crypto_tickers_etl' AIRFLOW_CTX_TASK_ID='load' AIRFLOW_CTX_EXECUTION_DATE='2024-09-06T00:00:00+00:00' AIRFLOW_CTX_TRY_NUMBER='1' AIRFLOW_CTX_DAG_RUN_ID='scheduled__2024-09-06T00:00:00+00:00'
[2024-10-21T02:34:32.289+0000] {taskinstance.py:1937} ERROR - Task failed with exception
Traceback (most recent call last):
  File "/home/airflow/.local/lib/python3.8/site-packages/sqlalchemy/engine/base.py", line 1910, in _execute_context
    self.dialect.do_execute(
  File "/home/airflow/.local/lib/python3.8/site-packages/sqlalchemy/engine/default.py", line 736, in do_execute
    cursor.execute(statement, parameters)
psycopg2.errors.UniqueViolation: duplicate key value violates unique constraint "pg_type_typname_nsp_index"
DETAIL:  Key (typname, typnamespace)=(crypto_tickers, 24643) already exists.


The above exception was the direct cause of the following exception:

Traceback (most recent call last):
  File "/home/airflow/.local/lib/python3.8/site-packages/airflow/operators/python.py", line 192, in execute
    return_value = self.execute_callable()
  File "/home/airflow/.local/lib/python3.8/site-packages/airflow/operators/python.py", line 209, in execute_callable
    return self.python_callable(*self.op_args, **self.op_kwargs)
  File "/opt/airflow/dags/crypto_etl_dag.py", line 41, in load_to_db
    df.to_sql('crypto_tickers', con=engine, schema='data', if_exists='replace', index=False)
  File "/home/airflow/.local/lib/python3.8/site-packages/pandas/core/generic.py", line 2878, in to_sql
    return sql.to_sql(
  File "/home/airflow/.local/lib/python3.8/site-packages/pandas/io/sql.py", line 769, in to_sql
    return pandas_sql.to_sql(
  File "/home/airflow/.local/lib/python3.8/site-packages/pandas/io/sql.py", line 1910, in to_sql
    table = self.prep_table(
  File "/home/airflow/.local/lib/python3.8/site-packages/pandas/io/sql.py", line 1814, in prep_table
    table.create()
  File "/home/airflow/.local/lib/python3.8/site-packages/pandas/io/sql.py", line 914, in create
    self._execute_create()
  File "/home/airflow/.local/lib/python3.8/site-packages/pandas/io/sql.py", line 900, in _execute_create
    self.table.create(bind=self.pd_sql.con)
  File "/home/airflow/.local/lib/python3.8/site-packages/sqlalchemy/sql/schema.py", line 962, in create
    bind._run_ddl_visitor(ddl.SchemaGenerator, self, checkfirst=checkfirst)
  File "/home/airflow/.local/lib/python3.8/site-packages/sqlalchemy/engine/base.py", line 2221, in _run_ddl_visitor
    visitorcallable(self.dialect, self, **kwargs).traverse_single(element)
  File "/home/airflow/.local/lib/python3.8/site-packages/sqlalchemy/sql/visitors.py", line 524, in traverse_single
    return meth(obj, **kw)
  File "/home/airflow/.local/lib/python3.8/site-packages/sqlalchemy/sql/ddl.py", line 899, in visit_table
    self.connection.execute(
  File "/home/airflow/.local/lib/python3.8/site-packages/sqlalchemy/engine/base.py", line 1385, in execute
    return meth(self, multiparams, params, _EMPTY_EXECUTION_OPTS)
  File "/home/airflow/.local/lib/python3.8/site-packages/sqlalchemy/sql/ddl.py", line 80, in _execute_on_connection
    return connection._execute_ddl(
  File "/home/airflow/.local/lib/python3.8/site-packages/sqlalchemy/engine/base.py", line 1477, in _execute_ddl
    ret = self._execute_context(
  File "/home/airflow/.local/lib/python3.8/site-packages/sqlalchemy/engine/base.py", line 1953, in _execute_context
    self._handle_dbapi_exception(
  File "/home/airflow/.local/lib/python3.8/site-packages/sqlalchemy/engine/base.py", line 2134, in _handle_dbapi_exception
    util.raise_(
  File "/home/airflow/.local/lib/python3.8/site-packages/sqlalchemy/util/compat.py", line 211, in raise_
    raise exception
  File "/home/airflow/.local/lib/python3.8/site-packages/sqlalchemy/engine/base.py", line 1910, in _execute_context
    self.dialect.do_execute(
  File "/home/airflow/.local/lib/python3.8/site-packages/sqlalchemy/engine/default.py", line 736, in do_execute
    cursor.execute(statement, parameters)
sqlalchemy.exc.IntegrityError: (psycopg2.errors.UniqueViolation) duplicate key value violates unique constraint "pg_type_typname_nsp_index"
DETAIL:  Key (typname, typnamespace)=(crypto_tickers, 24643) already exists.

[SQL: 
CREATE TABLE data.crypto_tickers (
	base TEXT, 
	target TEXT, 
	last FLOAT(53), 
	volume FLOAT(53), 
	converted_last TEXT, 
	converted_volume TEXT, 
	timestamp TIMESTAMP WITH TIME ZONE, 
	last_traded_at TIMESTAMP WITH TIME ZONE, 
	last_fetch_at TIMESTAMP WITH TIME ZONE, 
	data_ingested_at TIMESTAMP WITHOUT TIME ZONE
)

]
(Background on this error at: https://sqlalche.me/e/14/gkpj)
[2024-10-21T02:34:32.324+0000] {taskinstance.py:1400} INFO - Marking task as UP_FOR_RETRY. dag_id=crypto_tickers_etl, task_id=load, execution_date=20240906T000000, start_date=20241021T023431, end_date=20241021T023432
[2024-10-21T02:34:32.351+0000] {standard_task_runner.py:104} ERROR - Failed to execute job 674 for task load ((psycopg2.errors.UniqueViolation) duplicate key value violates unique constraint "pg_type_typname_nsp_index"
DETAIL:  Key (typname, typnamespace)=(crypto_tickers, 24643) already exists.

[SQL: 
CREATE TABLE data.crypto_tickers (
	base TEXT, 
	target TEXT, 
	last FLOAT(53), 
	volume FLOAT(53), 
	converted_last TEXT, 
	converted_volume TEXT, 
	timestamp TIMESTAMP WITH TIME ZONE, 
	last_traded_at TIMESTAMP WITH TIME ZONE, 
	last_fetch_at TIMESTAMP WITH TIME ZONE, 
	data_ingested_at TIMESTAMP WITHOUT TIME ZONE
)

]
(Background on this error at: https://sqlalche.me/e/14/gkpj); 197)
[2024-10-21T02:34:32.409+0000] {local_task_job_runner.py:228} INFO - Task exited with return code 1
[2024-10-21T02:34:32.573+0000] {taskinstance.py:2778} INFO - 0 downstream tasks scheduled from follow-on schedule check
