[2024-10-20T10:21:19.565+0000] {taskinstance.py:1159} INFO - Dependencies all met for dep_context=non-requeueable deps ti=<TaskInstance: covid_etl.load scheduled__2024-09-08T00:00:00+00:00 [queued]>
[2024-10-20T10:21:19.608+0000] {taskinstance.py:1159} INFO - Dependencies all met for dep_context=requeueable deps ti=<TaskInstance: covid_etl.load scheduled__2024-09-08T00:00:00+00:00 [queued]>
[2024-10-20T10:21:19.619+0000] {taskinstance.py:1361} INFO - Starting attempt 2 of 2
[2024-10-20T10:21:19.700+0000] {taskinstance.py:1382} INFO - Executing <Task(PythonOperator): load> on 2024-09-08 00:00:00+00:00
[2024-10-20T10:21:19.731+0000] {standard_task_runner.py:57} INFO - Started process 133 to run task
[2024-10-20T10:21:19.749+0000] {standard_task_runner.py:84} INFO - Running: ['***', 'tasks', 'run', 'covid_etl', 'load', 'scheduled__2024-09-08T00:00:00+00:00', '--job-id', '301', '--raw', '--subdir', 'DAGS_FOLDER/covid_dag.py', '--cfg-path', '/tmp/tmp5vm94q94']
[2024-10-20T10:21:19.753+0000] {standard_task_runner.py:85} INFO - Job 301: Subtask load
[2024-10-20T10:21:20.182+0000] {task_command.py:416} INFO - Running <TaskInstance: covid_etl.load scheduled__2024-09-08T00:00:00+00:00 [running]> on host fc8bd2e528fe
[2024-10-20T10:21:20.656+0000] {taskinstance.py:1662} INFO - Exporting env vars: AIRFLOW_CTX_DAG_OWNER='***' AIRFLOW_CTX_DAG_ID='covid_etl' AIRFLOW_CTX_TASK_ID='load' AIRFLOW_CTX_EXECUTION_DATE='2024-09-08T00:00:00+00:00' AIRFLOW_CTX_TRY_NUMBER='2' AIRFLOW_CTX_DAG_RUN_ID='scheduled__2024-09-08T00:00:00+00:00'
[2024-10-20T10:21:20.920+0000] {taskinstance.py:1937} ERROR - Task failed with exception
Traceback (most recent call last):
  File "/home/airflow/.local/lib/python3.8/site-packages/sqlalchemy/engine/base.py", line 1910, in _execute_context
    self.dialect.do_execute(
  File "/home/airflow/.local/lib/python3.8/site-packages/sqlalchemy/engine/default.py", line 736, in do_execute
    cursor.execute(statement, parameters)
psycopg2.errors.UniqueViolation: duplicate key value violates unique constraint "pg_type_typname_nsp_index"
DETAIL:  Key (typname, typnamespace)=(covid_cases_by_province, 24643) already exists.


The above exception was the direct cause of the following exception:

Traceback (most recent call last):
  File "/home/airflow/.local/lib/python3.8/site-packages/airflow/operators/python.py", line 192, in execute
    return_value = self.execute_callable()
  File "/home/airflow/.local/lib/python3.8/site-packages/airflow/operators/python.py", line 209, in execute_callable
    return self.python_callable(*self.op_args, **self.op_kwargs)
  File "/opt/airflow/dags/covid_dag.py", line 33, in load_to_db
    df.to_sql('covid_cases_by_province', con=engine, schema='data', if_exists='replace', index=False)
  File "/home/airflow/.local/lib/python3.8/site-packages/pandas/core/generic.py", line 2878, in to_sql
    return sql.to_sql(
  File "/home/airflow/.local/lib/python3.8/site-packages/pandas/io/sql.py", line 769, in to_sql
    return pandas_sql.to_sql(
  File "/home/airflow/.local/lib/python3.8/site-packages/pandas/io/sql.py", line 1910, in to_sql
    table = self.prep_table(
  File "/home/airflow/.local/lib/python3.8/site-packages/pandas/io/sql.py", line 1814, in prep_table
    table.create()
  File "/home/airflow/.local/lib/python3.8/site-packages/pandas/io/sql.py", line 914, in create
    self._execute_create()
  File "/home/airflow/.local/lib/python3.8/site-packages/pandas/io/sql.py", line 900, in _execute_create
    self.table.create(bind=self.pd_sql.con)
  File "/home/airflow/.local/lib/python3.8/site-packages/sqlalchemy/sql/schema.py", line 962, in create
    bind._run_ddl_visitor(ddl.SchemaGenerator, self, checkfirst=checkfirst)
  File "/home/airflow/.local/lib/python3.8/site-packages/sqlalchemy/engine/base.py", line 2221, in _run_ddl_visitor
    visitorcallable(self.dialect, self, **kwargs).traverse_single(element)
  File "/home/airflow/.local/lib/python3.8/site-packages/sqlalchemy/sql/visitors.py", line 524, in traverse_single
    return meth(obj, **kw)
  File "/home/airflow/.local/lib/python3.8/site-packages/sqlalchemy/sql/ddl.py", line 899, in visit_table
    self.connection.execute(
  File "/home/airflow/.local/lib/python3.8/site-packages/sqlalchemy/engine/base.py", line 1385, in execute
    return meth(self, multiparams, params, _EMPTY_EXECUTION_OPTS)
  File "/home/airflow/.local/lib/python3.8/site-packages/sqlalchemy/sql/ddl.py", line 80, in _execute_on_connection
    return connection._execute_ddl(
  File "/home/airflow/.local/lib/python3.8/site-packages/sqlalchemy/engine/base.py", line 1477, in _execute_ddl
    ret = self._execute_context(
  File "/home/airflow/.local/lib/python3.8/site-packages/sqlalchemy/engine/base.py", line 1953, in _execute_context
    self._handle_dbapi_exception(
  File "/home/airflow/.local/lib/python3.8/site-packages/sqlalchemy/engine/base.py", line 2134, in _handle_dbapi_exception
    util.raise_(
  File "/home/airflow/.local/lib/python3.8/site-packages/sqlalchemy/util/compat.py", line 211, in raise_
    raise exception
  File "/home/airflow/.local/lib/python3.8/site-packages/sqlalchemy/engine/base.py", line 1910, in _execute_context
    self.dialect.do_execute(
  File "/home/airflow/.local/lib/python3.8/site-packages/sqlalchemy/engine/default.py", line 736, in do_execute
    cursor.execute(statement, parameters)
sqlalchemy.exc.IntegrityError: (psycopg2.errors.UniqueViolation) duplicate key value violates unique constraint "pg_type_typname_nsp_index"
DETAIL:  Key (typname, typnamespace)=(covid_cases_by_province, 24643) already exists.

[SQL: 
CREATE TABLE data.covid_cases_by_province (
	year BIGINT, 
	weeknum BIGINT, 
	province TEXT, 
	new_case BIGINT, 
	total_case BIGINT, 
	new_case_excludeabroad BIGINT, 
	total_case_excludeabroad BIGINT, 
	new_death BIGINT, 
	total_death BIGINT, 
	update_date TEXT, 
	data_ingested_at TIMESTAMP WITHOUT TIME ZONE
)

]
(Background on this error at: https://sqlalche.me/e/14/gkpj)
[2024-10-20T10:21:21.010+0000] {taskinstance.py:1400} INFO - Marking task as FAILED. dag_id=covid_etl, task_id=load, execution_date=20240908T000000, start_date=20241020T102119, end_date=20241020T102121
[2024-10-20T10:21:21.125+0000] {standard_task_runner.py:104} ERROR - Failed to execute job 301 for task load ((psycopg2.errors.UniqueViolation) duplicate key value violates unique constraint "pg_type_typname_nsp_index"
DETAIL:  Key (typname, typnamespace)=(covid_cases_by_province, 24643) already exists.

[SQL: 
CREATE TABLE data.covid_cases_by_province (
	year BIGINT, 
	weeknum BIGINT, 
	province TEXT, 
	new_case BIGINT, 
	total_case BIGINT, 
	new_case_excludeabroad BIGINT, 
	total_case_excludeabroad BIGINT, 
	new_death BIGINT, 
	total_death BIGINT, 
	update_date TEXT, 
	data_ingested_at TIMESTAMP WITHOUT TIME ZONE
)

]
(Background on this error at: https://sqlalche.me/e/14/gkpj); 133)
[2024-10-20T10:21:21.246+0000] {local_task_job_runner.py:228} INFO - Task exited with return code 1
[2024-10-20T10:21:21.314+0000] {taskinstance.py:2778} INFO - 0 downstream tasks scheduled from follow-on schedule check
