[2024-10-21T15:43:02.073+0000] {taskinstance.py:1159} INFO - Dependencies all met for dep_context=non-requeueable deps ti=<TaskInstance: crypto_tickers1_etl.load scheduled__2024-09-10T00:00:00+00:00 [queued]>
[2024-10-21T15:43:02.105+0000] {taskinstance.py:1159} INFO - Dependencies all met for dep_context=requeueable deps ti=<TaskInstance: crypto_tickers1_etl.load scheduled__2024-09-10T00:00:00+00:00 [queued]>
[2024-10-21T15:43:02.108+0000] {taskinstance.py:1361} INFO - Starting attempt 1 of 2
[2024-10-21T15:43:02.168+0000] {taskinstance.py:1382} INFO - Executing <Task(PythonOperator): load> on 2024-09-10 00:00:00+00:00
[2024-10-21T15:43:02.204+0000] {standard_task_runner.py:57} INFO - Started process 159 to run task
[2024-10-21T15:43:02.230+0000] {standard_task_runner.py:84} INFO - Running: ['***', 'tasks', 'run', 'crypto_tickers1_etl', 'load', 'scheduled__2024-09-10T00:00:00+00:00', '--job-id', '871', '--raw', '--subdir', 'DAGS_FOLDER/25_6421605435_dag.py', '--cfg-path', '/tmp/tmpeblise7u']
[2024-10-21T15:43:02.249+0000] {standard_task_runner.py:85} INFO - Job 871: Subtask load
[2024-10-21T15:43:02.518+0000] {task_command.py:416} INFO - Running <TaskInstance: crypto_tickers1_etl.load scheduled__2024-09-10T00:00:00+00:00 [running]> on host c5bd55ce4ed9
[2024-10-21T15:43:02.932+0000] {taskinstance.py:1662} INFO - Exporting env vars: AIRFLOW_CTX_DAG_OWNER='***' AIRFLOW_CTX_DAG_ID='crypto_tickers1_etl' AIRFLOW_CTX_TASK_ID='load' AIRFLOW_CTX_EXECUTION_DATE='2024-09-10T00:00:00+00:00' AIRFLOW_CTX_TRY_NUMBER='1' AIRFLOW_CTX_DAG_RUN_ID='scheduled__2024-09-10T00:00:00+00:00'
[2024-10-21T15:43:02.955+0000] {taskinstance.py:1937} ERROR - Task failed with exception
Traceback (most recent call last):
  File "/home/airflow/.local/lib/python3.8/site-packages/airflow/operators/python.py", line 192, in execute
    return_value = self.execute_callable()
  File "/home/airflow/.local/lib/python3.8/site-packages/airflow/operators/python.py", line 209, in execute_callable
    return self.python_callable(*self.op_args, **self.op_kwargs)
  File "/opt/airflow/dags/25_6421605435_dag.py", line 51, in load_to_db
    df = pd.read_csv(data_path, parse_dates=['timestamp', 'last_traded_at', 'last_fetch_at'])
  File "/home/airflow/.local/lib/python3.8/site-packages/pandas/io/parsers/readers.py", line 912, in read_csv
    return _read(filepath_or_buffer, kwds)
  File "/home/airflow/.local/lib/python3.8/site-packages/pandas/io/parsers/readers.py", line 577, in _read
    parser = TextFileReader(filepath_or_buffer, **kwds)
  File "/home/airflow/.local/lib/python3.8/site-packages/pandas/io/parsers/readers.py", line 1407, in __init__
    self._engine = self._make_engine(f, self.engine)
  File "/home/airflow/.local/lib/python3.8/site-packages/pandas/io/parsers/readers.py", line 1661, in _make_engine
    self.handles = get_handle(
  File "/home/airflow/.local/lib/python3.8/site-packages/pandas/io/common.py", line 859, in get_handle
    handle = open(
FileNotFoundError: [Errno 2] No such file or directory: 'None'
[2024-10-21T15:43:03.026+0000] {taskinstance.py:1400} INFO - Marking task as UP_FOR_RETRY. dag_id=crypto_tickers1_etl, task_id=load, execution_date=20240910T000000, start_date=20241021T154302, end_date=20241021T154303
[2024-10-21T15:43:03.077+0000] {standard_task_runner.py:104} ERROR - Failed to execute job 871 for task load ([Errno 2] No such file or directory: 'None'; 159)
[2024-10-21T15:43:03.143+0000] {local_task_job_runner.py:228} INFO - Task exited with return code 1
[2024-10-21T15:43:03.201+0000] {taskinstance.py:2778} INFO - 0 downstream tasks scheduled from follow-on schedule check
