[2024-10-21T02:28:26.434+0000] {taskinstance.py:1159} INFO - Dependencies all met for dep_context=non-requeueable deps ti=<TaskInstance: crypto_history_etl.transform manual__2024-10-21T02:28:17.755169+00:00 [queued]>
[2024-10-21T02:28:26.460+0000] {taskinstance.py:1159} INFO - Dependencies all met for dep_context=requeueable deps ti=<TaskInstance: crypto_history_etl.transform manual__2024-10-21T02:28:17.755169+00:00 [queued]>
[2024-10-21T02:28:26.461+0000] {taskinstance.py:1361} INFO - Starting attempt 1 of 2
[2024-10-21T02:28:26.487+0000] {taskinstance.py:1382} INFO - Executing <Task(PythonOperator): transform> on 2024-10-21 02:28:17.755169+00:00
[2024-10-21T02:28:26.500+0000] {standard_task_runner.py:57} INFO - Started process 161 to run task
[2024-10-21T02:28:26.505+0000] {standard_task_runner.py:84} INFO - Running: ['***', 'tasks', 'run', 'crypto_history_etl', 'transform', 'manual__2024-10-21T02:28:17.755169+00:00', '--job-id', '633', '--raw', '--subdir', 'DAGS_FOLDER/crypto_etl_dag.py', '--cfg-path', '/tmp/tmpvjiunmxq']
[2024-10-21T02:28:26.507+0000] {standard_task_runner.py:85} INFO - Job 633: Subtask transform
[2024-10-21T02:28:26.599+0000] {task_command.py:416} INFO - Running <TaskInstance: crypto_history_etl.transform manual__2024-10-21T02:28:17.755169+00:00 [running]> on host 3c07e08c9ecc
[2024-10-21T02:28:26.746+0000] {taskinstance.py:1662} INFO - Exporting env vars: AIRFLOW_CTX_DAG_OWNER='***' AIRFLOW_CTX_DAG_ID='crypto_history_etl' AIRFLOW_CTX_TASK_ID='transform' AIRFLOW_CTX_EXECUTION_DATE='2024-10-21T02:28:17.755169+00:00' AIRFLOW_CTX_TRY_NUMBER='1' AIRFLOW_CTX_DAG_RUN_ID='manual__2024-10-21T02:28:17.755169+00:00'
[2024-10-21T02:28:26.782+0000] {taskinstance.py:1937} ERROR - Task failed with exception
Traceback (most recent call last):
  File "/home/airflow/.local/lib/python3.8/site-packages/airflow/operators/python.py", line 192, in execute
    return_value = self.execute_callable()
  File "/home/airflow/.local/lib/python3.8/site-packages/airflow/operators/python.py", line 209, in execute_callable
    return self.python_callable(*self.op_args, **self.op_kwargs)
  File "/opt/airflow/dags/crypto_etl_dag.py", line 24, in transform_data
    prices = data['prices']
KeyError: 'prices'
[2024-10-21T02:28:26.803+0000] {taskinstance.py:1400} INFO - Marking task as UP_FOR_RETRY. dag_id=crypto_history_etl, task_id=transform, execution_date=20241021T022817, start_date=20241021T022826, end_date=20241021T022826
[2024-10-21T02:28:26.828+0000] {standard_task_runner.py:104} ERROR - Failed to execute job 633 for task transform ('prices'; 161)
[2024-10-21T02:28:26.883+0000] {local_task_job_runner.py:228} INFO - Task exited with return code 1
[2024-10-21T02:28:26.922+0000] {taskinstance.py:2778} INFO - 0 downstream tasks scheduled from follow-on schedule check
