[2024-10-21T02:28:19.707+0000] {taskinstance.py:1159} INFO - Dependencies all met for dep_context=non-requeueable deps ti=<TaskInstance: crypto_history_etl.extract scheduled__2024-09-06T00:00:00+00:00 [queued]>
[2024-10-21T02:28:19.777+0000] {taskinstance.py:1159} INFO - Dependencies all met for dep_context=requeueable deps ti=<TaskInstance: crypto_history_etl.extract scheduled__2024-09-06T00:00:00+00:00 [queued]>
[2024-10-21T02:28:19.780+0000] {taskinstance.py:1361} INFO - Starting attempt 1 of 2
[2024-10-21T02:28:20.311+0000] {taskinstance.py:1382} INFO - Executing <Task(PythonOperator): extract> on 2024-09-06 00:00:00+00:00
[2024-10-21T02:28:20.350+0000] {standard_task_runner.py:57} INFO - Started process 121 to run task
[2024-10-21T02:28:20.361+0000] {standard_task_runner.py:84} INFO - Running: ['***', 'tasks', 'run', 'crypto_history_etl', 'extract', 'scheduled__2024-09-06T00:00:00+00:00', '--job-id', '618', '--raw', '--subdir', 'DAGS_FOLDER/crypto_etl_dag.py', '--cfg-path', '/tmp/tmpumlg94k9']
[2024-10-21T02:28:20.377+0000] {standard_task_runner.py:85} INFO - Job 618: Subtask extract
[2024-10-21T02:28:20.628+0000] {task_command.py:416} INFO - Running <TaskInstance: crypto_history_etl.extract scheduled__2024-09-06T00:00:00+00:00 [running]> on host 3c07e08c9ecc
[2024-10-21T02:28:20.830+0000] {taskinstance.py:1662} INFO - Exporting env vars: AIRFLOW_CTX_DAG_OWNER='***' AIRFLOW_CTX_DAG_ID='crypto_history_etl' AIRFLOW_CTX_TASK_ID='extract' AIRFLOW_CTX_EXECUTION_DATE='2024-09-06T00:00:00+00:00' AIRFLOW_CTX_TRY_NUMBER='1' AIRFLOW_CTX_DAG_RUN_ID='scheduled__2024-09-06T00:00:00+00:00'
[2024-10-21T02:28:21.282+0000] {taskinstance.py:1937} ERROR - Task failed with exception
Traceback (most recent call last):
  File "/home/airflow/.local/lib/python3.8/site-packages/requests/models.py", line 960, in json
    return complexjson.loads(self.content.decode(encoding), **kwargs)
  File "/usr/local/lib/python3.8/json/__init__.py", line 357, in loads
    return _default_decoder.decode(s)
  File "/usr/local/lib/python3.8/json/decoder.py", line 337, in decode
    obj, end = self.raw_decode(s, idx=_w(s, 0).end())
  File "/usr/local/lib/python3.8/json/decoder.py", line 355, in raw_decode
    raise JSONDecodeError("Expecting value", s, err.value) from None
json.decoder.JSONDecodeError: Expecting value: line 1 column 1 (char 0)

During handling of the above exception, another exception occurred:

Traceback (most recent call last):
  File "/home/airflow/.local/lib/python3.8/site-packages/airflow/operators/python.py", line 192, in execute
    return_value = self.execute_callable()
  File "/home/airflow/.local/lib/python3.8/site-packages/airflow/operators/python.py", line 209, in execute_callable
    return self.python_callable(*self.op_args, **self.op_kwargs)
  File "/opt/airflow/dags/crypto_etl_dag.py", line 18, in extract_data
    data = response.json()
  File "/home/airflow/.local/lib/python3.8/site-packages/requests/models.py", line 968, in json
    raise RequestsJSONDecodeError(e.msg, e.doc, e.pos)
requests.exceptions.JSONDecodeError: Expecting value: line 1 column 1 (char 0)
[2024-10-21T02:28:21.316+0000] {taskinstance.py:1400} INFO - Marking task as UP_FOR_RETRY. dag_id=crypto_history_etl, task_id=extract, execution_date=20240906T000000, start_date=20241021T022819, end_date=20241021T022821
[2024-10-21T02:28:21.355+0000] {standard_task_runner.py:104} ERROR - Failed to execute job 618 for task extract (Expecting value: line 1 column 1 (char 0); 121)
[2024-10-21T02:28:21.438+0000] {local_task_job_runner.py:228} INFO - Task exited with return code 1
[2024-10-21T02:28:21.514+0000] {taskinstance.py:2778} INFO - 0 downstream tasks scheduled from follow-on schedule check
